Workbook

Sheet Sheet1
A3: Row Labels
A4: 3. Order Entry / Completion
A5: 4. Rx Setup
A6: 5. Claims to Adjudicate - New Rx's
A7: 6. Benefits Verification - New Rx's
A8: 7. Rx Verification
A9: 9. Patients to Contact - Refills
A10: A. Patients to Contact - New Rx's
A11: B. Patients to Contact - Refills
A12: C. Claims to Adjudicate - Refills
A13: E. Print Labels / Documentation
A14: F. Select Lots / Fill Rx
... A17: Grand Total

Sheet Order Last Event Mapping
A1: Order Last Event | B1: Queue | C1: Order Last Event Status | D1: Anovo DB (Order Last Event Status) | E1: Dashboard Status | F1: Status Type | G1: other | H1: SF | I1: roll exhaust
A2: 1st eRx Attempt | B2: B. Patients to Contact - Refills | C2: Patients to Contact - Scheduling Shipment | D2: Patients to Contact - Scheduling Shipment | F2: Active | G2: Utilize if 1st erx attempt is made to obtain new prescription while in queue B | J2: All
A3: 1st eRx Attempt | B3: I. Rx Expiration / Zero Refills | C3: New Rx Needed - 1st eRx Attempt | D3: New Rx Needed - 1st eRx Attempt | F3: Active | G3: Utilize for 1st attempt to obtain eRx Day 1 | H3: X | J3: All | K3: do we want attempts on external?
A4: 1st Fax Attempt | B4: B. Patients to Contact - Refills | C4: Patients to Contact - Scheduling Shipment | D4: Patients to Contact - Scheduling Shipment | F4: Active | G4: Utilize if 1st fax attempt is made to obtain new prescription while in queue B | J4: All
A5: 1st Fax Attempt | B5: C. Claims to Adjudicate - Refills | C5: Shipment Scheduled | D5: Shipment Scheduled | F5: Active | G5: Utilize if 1st fax attempt is sent for new prescription and patient has shipment scheduled | J5: All
A6: 1st Fax Attempt | B6: I. Rx Expiration / Zero Refills | C6: New Rx Needed - 1st Fax Attempt | D6: New Rx Needed - 1st Fax Attempt | F6: Active | G6: Utilize for 1st fax attempt to obtain new Rx Day 1 | H6: X | J6: All
A7: 1st Scheduling Attempt | B7: A. Patients to Contact - New Rx's | C7: Patients to Contact - Scheduling Shipment: 1st Attempt | D7: Patients to Contact - Scheduling Shipment: 1st Attempt | F7: Pending | G7: Utilize if 1st scheduling attempt has been made for new patient | J7: All
A8: 1st Scheduling Attempt | B8: B. Patients to Contact - Refills | C8: Patients to Contact - Scheduling Shipment: 1st Attempt | D8: Patients to Contact - Scheduling Shipment: 1st Attempt | F8: Active | G8: Utilize if 1st scheduling attempt has been made for refill | J8: All
A9: 2nd eRx Attempt | B9: B. Patients to Contact - Refills | C9: Patients to Contact - Scheduling Shipment | D9: Patients to Contact - Scheduling Shipment | F9: Active | G9: Utilize if 2nd erx attempt is made to obtain new prescription while in queue B | J9: All
A10: 2nd eRx Attempt | B10: I. Rx Expiration / Zero Refills | C10: New Rx Needed - 2nd eRx Attempt | D10: New Rx Needed - 2nd eRx Attempt | F10: Active | G10: Utilize for 2nd attempt to obtain eRx | H10: X | J10: All | K10: do we want attempts on external?
A11: 2nd Fax Attempt | B11: B. Patients to Contact - Refills | C11: Patients to Contact - Scheduling Shipment | D11: Patients to Contact - Scheduling Shipment | F11: Active | G11: Utilize if 2nd fax attempt is made to obtain new prescription while in queue B | J11: All
A12: 2nd Fax Attempt | B12: I. Rx Expiration / Zero Refills | C12: New Rx Needed - 2nd Fax Attempt | D12: New Rx Needed - 2nd Fax Attempt | F12: Active | G12: Utilize for 2nd fax attempt to obtain new Rx Day 4 | H12: X | J12: All
A13: 2nd Scheduling Attempt | B13: A. Patients to Contact - New Rx's | C13: Patients to Contact - Scheduling Shipment: 2nd Attempt | D13: Patients to Contact - Scheduling Shipment: 2nd Attempt | F13: Pending | G13: Utilize if 2nd scheduling attempt has been made for new patient | J13: All
A14: 2nd Scheduling Attempt | B14: B. Patients to Contact - Refills | C14: Patients to Contact - Scheduling Shipment: 2nd Attempt | D14: Patients to Contact - Scheduling Shipment: 2nd Attempt | F14: Active | G14: Utilize if 2nd scheduling attempt has been made for refill | J14: All
A15: 3rd Scheduling Attempt | B15: A. Patients to Contact - New Rx's | C15: Patients to Contact - Scheduling Shipment: 3rd Attempt | D15: Patients to Contact - Scheduling Shipment: 3rd Attempt | F15: Pending | G15: Utilize if 3rd scheduling attempt has been made for new patient | J15: All
A16: 3rd Scheduling Attempt | B16: B. Patients to Contact - Refills | C16: Patients to Contact - Scheduling Shipment: 3rd Attempt | D16: Patients to Contact - Scheduling Shipment: 3rd Attempt | F16: Active | G16: Utilize if 3rd Scheduling attempt has been made for refill | J16: All
A17: 4th Scheduling Attempt | B17: A. Patients to Contact - New Rx's | C17: Patients to Contact - Scheduling Shipment: 4th Attempt | D17: Patients to Contact - Scheduling Shipment: 4th Attempt | F17: Pending | G17: Utilize if 4th scheduling attempt has been made for new patient ( WHEN MOVING ORDER FROM QUEUE A TO B, THE STATUS SHOULD CONTINUE TO PATIENT TO CONTACT: SCHEDULING SHIPMENT:5TH ATTEMPT IF 4TH ATTEMPT IS UNSUCESSFUL) | J17: All
A18: 4th Scheduling Attempt | B18: B. Patients to Contact - Refills | C18: Patients to Contact - Scheduling Shipment: 4th Attempt | D18: Patients to Contact - Scheduling Shipment: 4th Attempt | F18: Pending | G18: Utilize if 4th scheduling attempt has been made for refill | J18: All
A19: 4th Scheduling Attempt | B19: B. Patients to Contact - Refills | C19: Patients to Contact - Scheduling Shipment: 4th Attempt | D19: Patients to Contact - Scheduling Shipment: 4th Attempt | F19: Active | G19: Utilize if 4th scheduling attempt has been made for refill | J19: All
A20: 5th Scheduling Attempt | B20: B. Patients to Contact - Refills | C20: Patients to Contact - Scheduling Shipment: 5th Attempt | D20: Patients to Contact - Scheduling Shipment: 5th Attempt | F20: Active | G20: Utilize if 5th scheduling attempt has been made for refill | J20: All
A21: 6th Scheduling Attempt | B21: B. Patients to Contact - Refills | C21: Patients to Contact - Scheduling Shipment: 6th Attempt | D21: Patients to Contact - Scheduling Shipment: 6th Attempt | F21: Active | G21: Utilize if 6th scheduling attempt has been made for refill | J21: All
A22: Call to schedule | B22: B. Patients to Contact - Refills | C22: Patients to Contact - Scheduling Shipment | D22: Patients to Contact - Scheduling Shipment | F22: Active | G22: Utilize if pharmacist wants outreach made to specific patient - probably do not call patients
A23: Called and left message with MDO rep | B23: 4. Rx Setup | C23: Rx Clarification Needed | D23: Called MDO for Rx clarification | F23: Pending | G23: Utilize if clarification needed, called MDO and left message with representative | H23: x (possibly) | J23: All
A24: Called and left message with MDO rep | B24: 7. Rx Verification | C24: Rx Verification | D24: Rx Verification | F24: Pending | G24: Utilized when a pharmacist needs verification and has called the MDO to obtain what is needed | J24: All
A25: Called and left Voicemail | B25: 4. Rx Setup | C25: Rx Clarification Needed | D25: Called MDO for Rx clarification | F25: Pending | G25: Utilize if clarification needed, called MDO and left voicemail | H25: x (possibly) | J25: All
A26: Called and left Voicemail | B26: I. Rx Expiration / Zero Refills | C26: New Rx Needed | D26: New Rx Needed | F26: Active | G26: Utilize if left VM with MD while trying to obtain new Rx | H26: X | J26: All
A27: Clarification Needed | B27: 4. Rx Setup | C27: Rx Clarification Needed | D27: Clarification Needed | F27: Pending | G27: Utilize if clarification needed, office is closed | H27: x (possibly) | J27: All
A28: Clarification Needed | B28: 7. Rx Verification | C28: Rx Clarification Needed | D28: Clarification Needed | F28: Pending | G28: Utilized when a pharmacist needs verification and has called the MDO to obtain what is needed
A29: Discontinue Rx | B29: 4. Rx Setup | C29: Rx Clarification Needed | D29: Rx Clarification Needed | F29: Pending | G29: Utilize if pharmacist needs to discontinue Rx due to annotation scanned back in | J29: All
A30: Discontinue Rx | B30: I. Rx Expiration / Zero Refills | F30: Active | G30: Utilize if pharmacist needs to dc previous prescription | J30: All | K30: pull status from the other Rx
A31: Drug on Hand - Dose Decrease | B31: B. Patients to Contact - Refills | C31: Drug on Hand - Dose Decrease | D31: Drug on Hand - Dose Decrease | F31: Active | G31: Utilize if patient has doh due to dose decrease | I31: Y | J31: All
A32: Drug on Hand - Dose Increase | B32: B. Patients to Contact - Refills | C32: Drug on Hand - Dose Increase | D32: Drug on Hand - Dose Increase | F32: Active | I32: Y
A33: Drug on Hand - Drug on Hold | B33: B. Patients to Contact - Refills | C33: Drug on Hand - Therapy on Hold | D33: Drug on Hand - Therapy on Hold | F33: Active | G33: Utilize for any other reason to hold therapy MD or Patient | I33: Y | J33: All
A34: Drug on Hand - Lab/ Testing | B34: B. Patients to Contact - Refills | C34: Drug on Hand - Lab/Testing | D34: Drug on Hand - Lab/Testing | F34: Active | I34: Y
A35: Drug on Hand - Medical Reason | B35: B. Patients to Contact - Refills | C35: Drug on Hand - Medical Reason | D35: Drug on Hand - Medical Reason | F35: Active | I35: Y
A36: Drug on Hand - Other | B36: B. Patients to Contact - Refills | C36: Drug on Hand - Other | D36: Drug on Hand - Other | F36: Active | I36: Y
A37: Drug on Hand - Patient Non-Compliant | B37: B. Patients to Contact - Refills | C37: Drug on Hand - Patient Non-Compliant | D37: Drug on Hand - Patient Non-Compliant | F37: Active | I37: Y
A38: Drug on Hand - Side Effects | B38: B. Patients to Contact - Refills | C38: Drug on Hand- Side Effects | D38: Drug on Hand- Side Effects | F38: Active | G38: Utilize if patient has DOH due to experiencing side effects | I38: Y
A39: Drug on Hand - Slow Titration | B39: B. Patients to Contact - Refills | C39: Drug on Hand - Slow Titration | D39: Drug on Hand - Slow Titration | F39: Active | G39: Utilize if patient is slow to titrate and has drug on hand | I39: Y | J39: Fintepla, Firdapse, Isturisa
A40: Drug on Hand - Tapering Off | B40: B. Patients to Contact - Refills | C40: Drug on Hand - Tapering Off Drug | D40: Drug on Hand - Tapering Off Drug | F40: Active | G40: Utilize if patient is tapering off medication | I40: Y | J40: Fintepla
...

Sheet Sheet2
A1: pk | B1: poptext
A2: 1027 | B2: 1st eRx Attempt | C2: =VLOOKUP(B2,'Order Last Event Mapping'!A:A,1,FALSE) -> 1st eRx Attempt
A3: 793 | B3: 1st Fax Attempt | C3: =VLOOKUP(B3,'Order Last Event Mapping'!A:A,1,FALSE) -> 1st Fax Attempt
A4: 786 | B4: 1st Scheduling Attempt | C4: =VLOOKUP(B4,'Order Last Event Mapping'!A:A,1,FALSE) -> 1st Scheduling Attempt
A5: 1068 | B5: 2nd eRx Attempt | C5: =VLOOKUP(B5,'Order Last Event Mapping'!A:A,1,FALSE) -> 2nd eRx Attempt
A6: 794 | B6: 2nd Fax Attempt | C6: =VLOOKUP(B6,'Order Last Event Mapping'!A:A,1,FALSE) -> 2nd Fax Attempt
A7: 787 | B7: 2nd Scheduling Attempt | C7: =VLOOKUP(B7,'Order Last Event Mapping'!A:A,1,FALSE) -> 2nd Scheduling Attempt
A8: 788 | B8: 3rd Scheduling Attempt | C8: =VLOOKUP(B8,'Order Last Event Mapping'!A:A,1,FALSE) -> 3rd Scheduling Attempt
A9: 791 | B9: 4th Scheduling Attempt | C9: =VLOOKUP(B9,'Order Last Event Mapping'!A:A,1,FALSE) -> 4th Scheduling Attempt
A10: 1069 | B10: 5th Scheduling Attempt | C10: =VLOOKUP(B10,'Order Last Event Mapping'!A:A,1,FALSE) -> 5th Scheduling Attempt
A11: 1070 | B11: 6th Scheduling Attempt | C11: =VLOOKUP(B11,'Order Last Event Mapping'!A:A,1,FALSE) -> 6th Scheduling Attempt
A12: 683 | B12: Add Prescriber to Order | C12: =VLOOKUP(B12,'Order Last Event Mapping'!A:A,1,FALSE) -> #N/A
A13: 1021 | B13: Alkindi Pharmacist review needed | C13: =VLOOKUP(B13,'Order Last Event Mapping'!A:A,1,FALSE) -> #N/A
... A320: 909 | B320: ZZZWS - Returned for Correction | C320: =VLOOKUP(B320,'Order Last Event Mapping'!A:A,1,FALSE) -> #N/A
